<?xml version="1.0" encoding="utf-8"?>
<!-- =================================================================================== -->
<!-- |    This document was autogenerated by xacro from mini.xacro                     | -->
<!-- |    EDITING THIS FILE BY HAND IS NOT RECOMMENDED                                 | -->
<!-- =================================================================================== -->
<robot name="scout_mini">
  <!--    <xacro:property name="track" value="0.3426" />
    <xacro:property name="wheelbase" value="0.3181"/>
    <xacro:property name="wheel_vertical_offset" value="-0.160000047342231" />-->
  <!-- Base link -->

  <!-- <link name="base_footprint"> -->
  <!-- <inertial> -->
    <!-- <mass value="0.0001"/> -->
    <!-- <origin xyz="0 0 0"/> -->
    <!-- <inertia ixx="0.0001" ixy="0.0" ixz="0.0" iyy="0.0001" iyz="0.0" izz="0.0001"/> -->
  <!-- </inertial> -->
  <!-- <visual> -->
    <!-- <origin rpy="0 0 0" xyz="0 0 0"/> -->
    <!-- <geometry> -->
      <!-- <box size="0.001 0.001 0.001"/> -->
    <!-- </geometry> -->
  <!-- </visual> -->
<!-- </link> -->
<!-- <gazebo reference="base_footprint"> -->
  <!-- <turnGravityOff>false</turnGravityOff> -->
<!-- </gazebo> -->
<!-- <joint name="base_footprint_joint" type="fixed"> -->
  <!-- <origin rpy="0 0 0" xyz="0 0 0.04"/> -->
  <!-- <parent link="base_footprint"/> -->
  <!-- <child link="base_link"/> -->
<!-- </joint> -->
<!-- <link name="base_footprint">
<joint name="base_footprint_joint" type="fixed">
    <origin rpy="0 0 0" xyz="0 0 0."/>
    <parent link="base_footprint"/>
    <child link="base_link"/>
  </joint> -->

  <!-- <link name="world" />

  <joint name="world_to_base" type="fixed">
  <origin rpy="0 0 0" xyz="0 0 0"/>
      <parent link="world"/>
      <child link="base_link"/>
  </joint>  -->



  <link name="base_link">
    <visual>
      <origin rpy="1.57 0 1.57" xyz="0 0 0.0"/>
      <geometry>
        <mesh filename="package://scout_description/meshes/scout_mini_base_link2.dae"/>
      </geometry>
    </visual>
    <collision>
      <origin rpy="1.57 0 1.57" xyz="0 0 0"/>
      <geometry>
        <mesh filename="package://scout_description/meshes/scout_mini_base_link2.dae"/>
      </geometry>
    </collision>
  </link>
  <!-- <joint name="chassis_link_joint" type="fixed">
        <origin xyz="0 0 ${wheel_radius - wheel_vertical_offset}" rpy="0 0 0" />
        <parent link="base_link" />
        <child link="chassis_link" />
    </joint> -->
  <link name="inertial_link">
    <inertial>
      <mass value="60"/>
      <origin xyz="0.0 0.0 0.0"/>
      <inertia ixx="2.288641" ixy="0" ixz="0" iyy="5.103976" iyz="0" izz="3.431465"/>
    </inertial>
  </link>
  <joint name="inertial_joint" type="fixed">
    <origin rpy="0 0 0" xyz="0 0 0"/>
    <parent link="base_link"/>
    <child link="inertial_link"/>
  </joint>
  <!-- For testing, hang the robot up in the air -->
  <!-- <link name="world" />
    <joint name="world_to_base_link=" type="fixed">
        <origin xyz="0 0 0.5" rpy="0 0 0" />
        <parent link="world"/>
        <child link="base_link"/>
    </joint> -->
  <link name="front_left_wheel_link">
    <!--<inertial>
                <mass value="3" />
                <origin
                        xyz="0.162297526351145 -0.159063056237197 -0.159999952657767"
                        rpy="0 0 0" />
                        <inertia ixx="0.7171" ixy="0" ixz="0" iyy="0.1361" iyz="0" izz="0.7171" />
                   </inertial>
            <visual>
                <origin xyz="0 0 0" rpy="0 0 0" />
                <geometry>
                    <mesh filename="package://scout_description/meshes/wheel.dae" />
                </geometry>
            </visual>-->
    <inertial>
      <mass value="3"/>
      <origin xyz="0 0 0"/>
      <inertia ixx="0.7171" ixy="0" ixz="0" iyy="0.7171" iyz="0" izz="0.1361"/>
      <!--<inertia ixx="0" ixy="0" ixz="0" iyy="0" iyz="0" izz="0" />-->
    </inertial>
    <visual>
      <origin rpy="0 0 0" xyz="0 0 0"/>
      <geometry>
        <mesh filename="package://scout_description/meshes/wheel.dae"/>
      </geometry>
    </visual>
    <collision>
      <origin rpy="0 0 0" xyz="0 0 0"/>
      <geometry>
        <mesh filename="package://scout_description/meshes/wheel.dae"/>
      </geometry>
    </collision>
  </link>
  <joint name="front_left_wheel" type="continuous">
    <!--<origin
                  xyz="0.14547 0.20835 -0.07424"
                  rpy="0 1.57 0" />-->
    <parent link="base_link"/>
    <child link="front_left_wheel_link"/>
    <origin rpy="-1.57 0 0" xyz="0.2319755 0.2082515 -0.100998"/>
    <axis rpy="0 0 0" xyz="0 0 -1"/>
  </joint>
  <link name="rear_left_wheel_link">
    <!--<inertial>
            <mass value="3" />
                <origin
                        xyz="0.162297526351148 0.159063056237198 -0.160000047342231"
                        rpy="0 0 0" />
                        <inertia ixx="0.7171" ixy="0" ixz="0" iyy="0.1361" iyz="0" izz="0.7171" />
            </inertial>
            <visual>
                <origin xyz="0 0 0" rpy="0 0 0" />
                <geometry>
                    <mesh filename="package://scout_description/meshes/wheel.dae" />
                </geometry>
            </visual>-->
    <inertial>
      <mass value="3"/>
      <origin xyz="0 0 0"/>
      <inertia ixx="0.7171" ixy="0" ixz="0" iyy="0.7171" iyz="0" izz="0.1361"/>
      <!--<inertia ixx="0" ixy="0" ixz="0" iyy="0" iyz="0" izz="0" />-->
    </inertial>
    <visual>
      <origin rpy="0 0 0" xyz="0 0 0"/>
      <geometry>
        <mesh filename="package://scout_description/meshes/wheel.dae"/>
      </geometry>
    </visual>
    <collision>
      <origin rpy="0 0 0" xyz="0 0 0"/>
      <geometry>
        <mesh filename="package://scout_description/meshes/wheel.dae"/>
      </geometry>
    </collision>
  </link>
  <joint name="rear_left_wheel" type="continuous">
    <!--<origin
                  xyz="-0.17453 0.20835 -0.07424"
                  rpy="0 -1.57 0" />-->
    <parent link="base_link"/>
    <child link="rear_left_wheel_link"/>
    <origin rpy="-1.57 0 0" xyz="-0.2319755 0.2082515 -0.100998"/>
    <axis rpy="0 0 0" xyz="0 0 -1"/>
  </joint>
  <link name="front_right_wheel_link">
    <!--<inertial>
            <mass value="3" />
                <origin
                        xyz="-0.235088020493741 -0.0575697183039213 -0.16000004734223"
                        rpy="0 0 0" />
                        <inertia ixx="0.7171" ixy="0" ixz="0" iyy="0.1361" iyz="0" izz="0.7171" />
            </inertial>
            <visual>
                <origin xyz="0 0 0" rpy="0 0 0" />
                <geometry>
                    <mesh filename="package://scout_description/meshes/wheel.dae" />
                </geometry>
            </visual>-->
    <inertial>
      <mass value="3"/>
      <origin xyz="0 0 0"/>
      <inertia ixx="0.7171" ixy="0" ixz="0" iyy="0.7171" iyz="0" izz="0.1361"/>
      <!--<inertia ixx="0" ixy="0" ixz="0" iyy="0" iyz="0" izz="0" />-->
    </inertial>
    <visual>
      <origin rpy="0 0 0" xyz="0 0 0"/>
      <geometry>
        <mesh filename="package://scout_description/meshes/wheel.dae"/>
      </geometry>
    </visual>
    <collision>
      <origin rpy="0 0 0" xyz="0 0 0"/>
      <geometry>
        <mesh filename="package://scout_description/meshes/wheel.dae"/>
      </geometry>
    </collision>
  </link>
  <joint name="front_right_wheel" type="continuous">
    <!--<origin
                  xyz="-0.17453 -0.24424 -0.07424"
                  rpy="0 -1.57 0" />-->
    <parent link="base_link"/>
    <child link="front_right_wheel_link"/>
    <origin rpy="1.57 0 0" xyz="0.2319755 -0.2082515 -0.099998"/>
    <axis rpy="0 0 0" xyz="0 0 -1"/>
  </joint>
  <link name="rear_right_wheel_link">
    <!--<inertial>
        <mass value="3" />
            <origin
                    xyz="0.235244832119832 -0.0585653794466942 -0.206994929144493"
                    rpy="0 0 0" />
                    <inertia ixx="0.7171" ixy="0" ixz="0" iyy="0.1361" iyz="0" izz="0.7171" />
        </inertial>
        <visual>
            <origin xyz="0 0 0" rpy="0 0 0" />
            <geometry>
                <mesh filename="package://scout_description/meshes/wheel.dae" />
            </geometry>
        </visual>-->
    <inertial>
      <mass value="3"/>
      <origin xyz="0 0 0"/>
      <inertia ixx="0.7171" ixy="0" ixz="0" iyy="0.7171" iyz="0" izz="0.1361"/>
      <!--<inertia ixx="0" ixy="0" ixz="0" iyy="0" iyz="0" izz="0" />-->
    </inertial>
    <visual>
      <origin rpy="0 0 0" xyz="0 0 0"/>
      <geometry>
        <mesh filename="package://scout_description/meshes/wheel.dae"/>
      </geometry>
    </visual>
    <collision>
      <origin rpy="0 0 0" xyz="0 0 0"/>
      <geometry>
        <mesh filename="package://scout_description/meshes/wheel.dae"/>
      </geometry>
    </collision>
  </link>
  <joint name="rear_right_wheel" type="continuous">
    <!--<origin
                  xyz="0.19247 -0.24486 -0.073441"
                  rpy="-0 1.57 0" />-->
    <parent link="base_link"/>
    <child link="rear_right_wheel_link"/>
    <origin rpy="1.57 0 0" xyz="-0.2319755 -0.2082515 -0.099998"/>
    <axis rpy="0 0 0" xyz="0 0 -1"/>
  </joint>


  <link name="hokuyo_link">
    <visual>
      <origin rpy="0 0 0" xyz="0 0 0.0"/>
      <geometry>
        <mesh filename="package://scout_description/meshes/hokuyo.dae"/>
        <!-- <box size="0.1 0.1 0.1"/> -->
      </geometry>
    </visual>
    <collision>
      <origin rpy="0 0 0" xyz="0 0 0"/>
      <geometry>
        <mesh filename="package://scout_description/meshes/hokuyo.dae"/>
        <!-- <box size="0.1 0.1 0.1"/> -->
      </geometry>
    </collision>
    <inertia>
      <mass value="1e-5" />
      <origin rpy="0 0 0" xyz="0 0 0.0"/>
      <inertia ixx="1e-6" ixy="0" ixz="0" iyy="1e-6" iyz="0" izz="1e-6"/>
    </inertia>
  </link>

  <joint name="hokuyo_joint" type="fixed">
    <parent link="base_link"/>
    <child link="hokuyo_link"/>
    <origin rpy="0 0 0" xyz="0 0 0.1"/>
    <axis rpy="0 0 0" xyz="0 1 0"/>
  </joint>

  <gazebo reference="hokuyo_joint">
    <material>Gazebo/Red</material>
    <mu1>0.2</mu1>
    <mu2>0.2</mu2>
  </gazebo>

  <gazebo reference="hokuyo_link">
    <sensor type="gpu_ray" name="hokuyo">
      <pose>0 0 0 0 0 0</pose>
      <visualize>false</visualize>
      <update_rate>40</update_rate>
      <ray>
        <scan>
          <horizontal>
            <samples>720</samples>
            <resolution>1</resolution>
            <min_angle>-1.570796</min_angle>
            <max_angle>1.570796</max_angle>
          </horizontal>
        </scan>
        <range>
          <min>0.10</min>
          <max>30.0</max>
          <resolution>0.05</resolution>
        </range>
      </ray>
      <plugin filename="libgazebo_ros_gpu_laser.so" name="gpu_laser">
        <alwaysOn>true</alwaysOn>
        <topicName>scan</topicName>
        <frameName>hokuyo_link</frameName>
      </plugin>
    </sensor>
  </gazebo>


  <link name="camera_link">
    <visual>
        <origin rpy="0 0 0" xyz="0 0 0" />
        <geometry>
            <box size="0.05 0.05 0.05"/>
        </geometry>
        <material name="">
            <color rgba="1.0 0 0 1.0" />
        </material>
    </visual>
    <collision>
        <origin rpy="0 0 0" xyz="0 0 0" />
        <geometry>
            <box size="0.05 0.05 0.05"/>
        </geometry>
    </collision>
    <inertial>
        <mass value="0.01" />
        <inertia ixx="0.0000001875" iyy="0.0000000018938" izz="0.0000001875" ixy="0.0" ixz="0.0" iyz="0.0" />
    </inertial>
</link>

<joint name="camera_joint" type="fixed">
  <parent link="base_link" />
  <child link="camera_link" />
  <origin rpy="0 0 0" xyz="0.3 0 0.05" />
<!-- <dynamics damping="0.7" friction="1"/> -->
</joint>

<gazebo reference="camera_link">
<material>Gazebo/Red</material>
  <sensor name="camera1" type="depth">
    <update_rate>30.0</update_rate>
    <camera>
      <horizontal_fov>1.047198</horizontal_fov>
      <image>
        <width>640</width>
        <height>480</height>
        <format>R8G8B8</format>
      </image>
      <clip>
        <near>0.05</near>
        <far>300</far>
      </clip>
    </camera>
    <!-- <plugin name="camera1_controller" filename="libgazebo_ros_camera.so"> -->
    <plugin name="camera1_controller" filename="libgazebo_ros_openni_kinect.so">
      <alwaysOn>true</alwaysOn>
      <baseline>0.2</baseline>
      <updateRate>0.0</updateRate>
      <cameraName>camera1</cameraName>
      <imageTopicName>/camera1/color/image_raw</imageTopicName>
      <cameraInfoTopicName>/camera1/color/camera_info</cameraInfoTopicName>
      <depthImageTopicName>/camera1/depth/image_raw</depthImageTopicName>
      <depthImageInfoTopicName>/camera1/depth/camera_info</depthImageInfoTopicName>
      <pointCloudCutoff>0.3</pointCloudCutoff>
      <pointCloudCutoffMax>7.0</pointCloudCutoffMax>
      <hackBaseline>0</hackBaseline>
      <frameName>camera_link</frameName>
      <distortionK1>0.00000001</distortionK1>
      <distortionK2>0.00000001</distortionK2>
      <distortionK3>0.00000001</distortionK3>
      <distortionT1>0.00000001</distortionT1>
      <distortionT2>0.00000001</distortionT2>
      <CxPrime>0</CxPrime>
      <Cx>0</Cx>
      <Cy>0</Cy>
      <focalLength>0</focalLength>
    </plugin>
  </sensor>
</gazebo>

  <!-- This file is a placeholder which is included by default from
       husky.urdf.xacro. If a robot is being customized and requires
       additional URDF, set the HUSKY_URDF_EXTRAS environment variable
       to the full path of the file you would like included. -->
  <!-- Additional definitions for simulation -->
  <!-- <gazebo reference="base_link">
        <material>Gazebo/Grey</material>
    </gazebo> -->
  <transmission name="front_right_wheel_trans" type="SimpleTransmission">
    <type>transmission_interface/SimpleTransmission</type>
    <actuator name="front_right_wheel_motor">
      <mechanicalReduction>1</mechanicalReduction>
    </actuator>
    <joint name="front_right_wheel">
      <hardwareInterface>hardware_interface/VelocityJointInterface</hardwareInterface>
    </joint>
  </transmission>
  <transmission name="front_left_wheel_trans" type="SimpleTransmission">
    <type>transmission_interface/SimpleTransmission</type>
    <actuator name="front_left_wheel_motor">
      <mechanicalReduction>1</mechanicalReduction>
    </actuator>
    <joint name="front_left_wheel">
      <hardwareInterface>hardware_interface/VelocityJointInterface</hardwareInterface>
    </joint>
  </transmission>
  <transmission name="rear_left_wheel_trans" type="SimpleTransmission">
    <type>transmission_interface/SimpleTransmission</type>
    <actuator name="rear_left_wheel_motor">
      <mechanicalReduction>1</mechanicalReduction>
    </actuator>
    <joint name="rear_left_wheel">
      <hardwareInterface>hardware_interface/VelocityJointInterface</hardwareInterface>
    </joint>
  </transmission>
  <transmission name="rear_right_wheel_trans" type="SimpleTransmission">
    <type>transmission_interface/SimpleTransmission</type>
    <actuator name="rear_right_wheel_motor">
      <mechanicalReduction>1</mechanicalReduction>
    </actuator>
    <joint name="rear_right_wheel">
      <hardwareInterface>hardware_interface/VelocityJointInterface</hardwareInterface>
    </joint>
  </transmission>
  <!-- Controller configurations -->
  <gazebo>
    <plugin filename="libgazebo_ros_control.so" name="gazebo_ros_control">
      <robotNamespace>/</robotNamespace>
    </plugin>
  </gazebo>
  <!-- kp spring constant, kd damping constant -->
  <gazebo>
    <mu1 value="1.0"/>
    <mu2 value="0.9"/>
    <kp value="10000000.0"/>
    <kd value="1.0"/>
    <fdir1 value="1 0 0"/>
    <minDepth value="0.001"/>
    <maxContacts value="64"/>
  </gazebo>
  <!-- <gazebo>
  <plugin filename="libgazebo_ros_diff_drive.so" name="differential_drive_controller_front">
    <rosDebugLevel>Debug</rosDebugLevel>
    <publishWheelTF>false</publishWheelTF>
    <publishTf>1</publishTf>
    <publishWheelJointState>false</publishWheelJointState>
    <alwaysOn>true</alwaysOn>
    <updateRate>100.0</updateRate>
    <leftJoint>front_left_wheel</leftJoint>
    <rightJoint>front_right_wheel</rightJoint>
    <wheelSeparation>0.45</wheelSeparation>
    <wheelDiameter>0.16</wheelDiameter>
    <broadcastTF>1</broadcastTF>
    <wheelTorque>30</wheelTorque>
    <wheelAcceleration>1.8</wheelAcceleration>
    <commandTopic>cmd_vel</commandTopic>
    <odometryFrame>odom</odometryFrame>
    <odometryTopic>odom</odometryTopic>
    <robotBaseFrame>base_link</robotBaseFrame>
  </plugin>
</gazebo> -->
  <gazebo>
        <plugin name="skid_steer_drive_controller" filename="libgazebo_ros_skid_steer_drive.so">
            <updateRate>100.0</updateRate>
            <robotNamespace>/</robotNamespace>
            <leftFrontJoint>front_left_wheel</leftFrontJoint>
            <rightFrontJoint>front_right_wheel</rightFrontJoint>
            <leftRearJoint>rear_left_wheel</leftRearJoint>
            <rightRearJoint>rear_right_wheel</rightRearJoint>
            <wheelSeparation>0.498</wheelSeparation>
            <wheelDiameter>0.32918</wheelDiameter>
            <robotBaseFrame>base_link</robotBaseFrame>
            <torque>1000</torque>
            <commandTopic>cmd_vel</commandTopic>
            <broadcastTF>true</broadcastTF>
            <odometryTopic>odom</odometryTopic>
            <odometryFrame>odom</odometryFrame>
            <covariance_x>0.000100</covariance_x>
            <covariance_y>0.000100</covariance_y>
            <covariance_yaw>0.010000</covariance_yaw>
        </plugin>
    </gazebo>
  <!-- <gazebo>
        <plugin name="object_controller" filename="libgazebo_ros_planar_move.so">
            <commandTopic>cmd_vel</commandTopic>
            <odometryTopic>odom</odometryTopic>
            <odometryFrame>odom</odometryFrame>
            <odometryRate>20.0</odometryRate>
            <robotBaseFrame>base_footprint</robotBaseFrame>
        </plugin>
    </gazebo> -->
</robot>
