<?xml version="1.0" encoding="utf-8"?>
<!-- =================================================================================== -->
<!-- |    This document was autogenerated by xacro from mini.xacro                     | -->
<!-- |    EDITING THIS FILE BY HAND IS NOT RECOMMENDED                                 | -->
<!-- =================================================================================== -->
<robot name="scout_mini">

  <!--    <xacro:property name="track" value="0.3426" />
    <xacro:property name="wheelbase" value="0.3181"/>
    <xacro:property name="wheel_vertical_offset" value="-0.160000047342231" />-->
  <!-- Base link -->


  <link name="base_link">
    <visual>
    <!-- <origin rpy="0 0 1.57" xyz="0 -10 -1.8"/> -->
      <origin rpy="1.57 0 0" xyz="0 0 0.0"/>
      <geometry>
        <mesh filename="package://scout_description/meshes/scout_mini_base_link2.dae"/>
      </geometry>
    </visual>
    <collision>
      <origin rpy="1.57 0 1.57" xyz="0 0 0"/>
      <geometry>
        <mesh filename="package://scout_description/meshes/scout_mini_base_link2.dae"/>
      </geometry>
    </collision>
  </link>
  <!-- <joint name="chassis_link_joint" type="fixed">
        <origin xyz="0 0 ${wheel_radius - wheel_vertical_offset}" rpy="0 0 0" />
        <parent link="base_link" />
        <child link="chassis_link" />
    </joint> -->
  <link name="inertial_link">
    <inertial>
      <mass value="60"/>
      <origin xyz="0.0 0.0 0.0"/>
      <inertia ixx="2.288641" ixy="0" ixz="0" iyy="5.103976" iyz="0" izz="3.431465"/>
    </inertial>
  </link>
  <joint name="inertial_joint" type="fixed">
    <origin rpy="0 0 0" xyz="0 0 0"/>
    <parent link="base_link"/>
    <child link="inertial_link"/>
  </joint>
  <!-- For testing, hang the robot up in the air -->
  <!-- <link name="world" />
    <joint name="world_to_base_link=" type="fixed">
        <origin xyz="0 0 0.5" rpy="0 0 0" />
        <parent link="world"/>
        <child link="base_link"/>
    </joint> -->
  <link name="front_left_wheel_link">
    <!--<inertial>
                <mass value="3" />
                <origin
                        xyz="0.162297526351145 -0.159063056237197 -0.159999952657767"
                        rpy="0 0 0" />
                        <inertia ixx="0.7171" ixy="0" ixz="0" iyy="0.1361" iyz="0" izz="0.7171" />
                   </inertial>
            <visual>
                <origin xyz="0 0 0" rpy="0 0 0" />
                <geometry>
                    <mesh filename="package://scout_description/meshes/wheel.dae" />
                </geometry>
            </visual>-->
    <inertial>
      <mass value="3"/>
      <origin xyz="0 0 0"/>
      <inertia ixx="0.7171" ixy="0" ixz="0" iyy="0.7171" iyz="0" izz="0.1361"/>
      <!--<inertia ixx="0" ixy="0" ixz="0" iyy="0" iyz="0" izz="0" />-->
    </inertial>
    <visual>
      <origin rpy="0 0 0" xyz="0 0 0"/>
      <geometry>
        <mesh filename="package://scout_description/meshes/wheel.dae"/>
      </geometry>
    </visual>
    <collision>
      <origin rpy="0 0 0" xyz="0 0 0"/>
      <geometry>
        <mesh filename="package://scout_description/meshes/wheel.dae"/>
      </geometry>
    </collision>
  </link>
  <joint name="front_left_wheel" type="continuous">
    <!--<origin
                  xyz="0.14547 0.20835 -0.07424"
                  rpy="0 1.57 0" />-->
    <parent link="base_link"/>
    <child link="front_left_wheel_link"/>
    <origin rpy="-1.57 0 0" xyz="0.2319755 0.2082515 -0.100998"/>
    <axis rpy="0 0 0" xyz="0 0 -1"/>
  </joint>
  <link name="rear_left_wheel_link">
    <!--<inertial>
            <mass value="3" />
                <origin
                        xyz="0.162297526351148 0.159063056237198 -0.160000047342231"
                        rpy="0 0 0" />
                        <inertia ixx="0.7171" ixy="0" ixz="0" iyy="0.1361" iyz="0" izz="0.7171" />
            </inertial>
            <visual>
                <origin xyz="0 0 0" rpy="0 0 0" />
                <geometry>
                    <mesh filename="package://scout_description/meshes/wheel.dae" />
                </geometry>
            </visual>-->
    <inertial>
      <mass value="3"/>
      <origin xyz="0 0 0"/>
      <inertia ixx="0.7171" ixy="0" ixz="0" iyy="0.7171" iyz="0" izz="0.1361"/>
      <!--<inertia ixx="0" ixy="0" ixz="0" iyy="0" iyz="0" izz="0" />-->
    </inertial>
    <visual>
      <origin rpy="0 0 0" xyz="0 0 0"/>
      <geometry>
        <mesh filename="package://scout_description/meshes/wheel.dae"/>
      </geometry>
    </visual>
    <collision>
      <origin rpy="0 0 0" xyz="0 0 0"/>
      <geometry>
        <mesh filename="package://scout_description/meshes/wheel.dae"/>
      </geometry>
    </collision>
  </link>
  <joint name="rear_left_wheel" type="continuous">
    <!--<origin
                  xyz="-0.17453 0.20835 -0.07424"
                  rpy="0 -1.57 0" />-->
    <parent link="base_link"/>
    <child link="rear_left_wheel_link"/>
    <origin rpy="-1.57 0 0" xyz="-0.2319755 0.2082515 -0.100998"/>
    <axis rpy="0 0 0" xyz="0 0 -1"/>
  </joint>
  <link name="front_right_wheel_link">
    <!--<inertial>
            <mass value="3" />
                <origin
                        xyz="-0.235088020493741 -0.0575697183039213 -0.16000004734223"
                        rpy="0 0 0" />
                        <inertia ixx="0.7171" ixy="0" ixz="0" iyy="0.1361" iyz="0" izz="0.7171" />
            </inertial>
            <visual>
                <origin xyz="0 0 0" rpy="0 0 0" />
                <geometry>
                    <mesh filename="package://scout_description/meshes/wheel.dae" />
                </geometry>
            </visual>-->
    <inertial>
      <mass value="3"/>
      <origin xyz="0 0 0"/>
      <inertia ixx="0.7171" ixy="0" ixz="0" iyy="0.7171" iyz="0" izz="0.1361"/>
      <!--<inertia ixx="0" ixy="0" ixz="0" iyy="0" iyz="0" izz="0" />-->
    </inertial>
    <visual>
      <origin rpy="0 0 0" xyz="0 0 0"/>
      <geometry>
        <mesh filename="package://scout_description/meshes/wheel.dae"/>
      </geometry>
    </visual>
    <collision>
      <origin rpy="0 0 0" xyz="0 0 0"/>
      <geometry>
        <mesh filename="package://scout_description/meshes/wheel.dae"/>
      </geometry>
    </collision>
  </link>
  <joint name="front_right_wheel" type="continuous">
    <!--<origin
                  xyz="-0.17453 -0.24424 -0.07424"
                  rpy="0 -1.57 0" />-->
    <parent link="base_link"/>
    <child link="front_right_wheel_link"/>
    <origin rpy="1.57 0 0" xyz="0.2319755 -0.2082515 -0.099998"/>
    <axis rpy="0 0 0" xyz="0 0 -1"/>
  </joint>
  <link name="rear_right_wheel_link">
    <!--<inertial>
        <mass value="3" />
            <origin
                    xyz="0.235244832119832 -0.0585653794466942 -0.206994929144493"
                    rpy="0 0 0" />
                    <inertia ixx="0.7171" ixy="0" ixz="0" iyy="0.1361" iyz="0" izz="0.7171" />
        </inertial>
        <visual>
            <origin xyz="0 0 0" rpy="0 0 0" />
            <geometry>
                <mesh filename="package://scout_description/meshes/wheel.dae" />
            </geometry>
        </visual>-->
    <inertial>
      <mass value="3"/>
      <origin xyz="0 0 0"/>
      <inertia ixx="0.7171" ixy="0" ixz="0" iyy="0.7171" iyz="0" izz="0.1361"/>
      <!--<inertia ixx="0" ixy="0" ixz="0" iyy="0" iyz="0" izz="0" />-->
    </inertial>
    <visual>
      <origin rpy="0 0 0" xyz="0 0 0"/>
      <geometry>
        <mesh filename="package://scout_description/meshes/wheel.dae"/>
      </geometry>
    </visual>
    <collision>
      <origin rpy="0 0 0" xyz="0 0 0"/>
      <geometry>
        <mesh filename="package://scout_description/meshes/wheel.dae"/>
      </geometry>
    </collision>
  </link>
  <joint name="rear_right_wheel" type="continuous">
    <!--<origin
                  xyz="0.19247 -0.24486 -0.073441"
                  rpy="-0 1.57 0" />-->
    <parent link="base_link"/>
    <child link="rear_right_wheel_link"/>
    <origin rpy="1.57 0 0" xyz="-0.2319755 -0.2082515 -0.099998"/>
    <axis rpy="0 0 0" xyz="0 0 -1"/>
  </joint>


  <link name="sat_link">
    <visual>
      <geometry>
        <box size="0.7 0.7 0.3"/>
      </geometry>
      <material name="silver">
        <color rgba="0.75 0.75 0.75 1"/>
      </material>
    </visual>
    <collision>
      <geometry>
        <box size="0 0 0"/>
      </geometry>
    </collision>
    <inertial>
      <mass value="1.0"/>
      <inertia ixx="0.015" iyy="0.0375" izz="0.0375" ixy="0" ixz="0" iyz="0"/>
    </inertial>
  </link>

  <joint name="sat_joint" type="fixed">
    <axis xyz="0 0 1"/>
    <parent link="base_link"/>
    <child link="sat_link"/>
    <origin rpy="0 0 0" xyz="0 0 0"/>
  </joint>

  <link name="sat_arm_link">
    <visual>
      <geometry>
        <cylinder length="1.6" radius="0.01"/>
      </geometry>
      <material name="silver">
        <color rgba="0.75 0.75 0.75 1"/>
      </material>
      <origin rpy="0 0 0" xyz="0 0 0.025"/>
      </visual>
      <collision>
        <geometry>
          <cylinder length="0" radius="0"/>
        </geometry>
        <origin rpy="0 0 0" xyz="0 0 0.025"/>
      </collision>
      <inertial>
        <mass value="1.0"/>
        <origin rpy="0 0 0" xyz="0 0 0.025"/>
        <inertia ixx="0.0027" iyy="0.0027" izz="0.005" ixy="0" ixz="0" iyz="0"/>
      </inertial>
  </link>

  <joint name="sat_arm_joint" type="fixed">
    <parent link="sat_link"/>
    <child link="sat_arm_link"/>
    <axis xyz="1 0 0"/>
    <origin rpy="1.57 0 0" xyz="0 0 0"/>
  </joint>

  <link name="sat_solar_left_link">
    <visual>
      <geometry>
        <box size="0.7 0.3 0.1"/>
      </geometry>
      <material name="silver">
        <color rgba="0.75 0.75 0.75 1"/>
      </material>
    </visual>
    <collision>
      <geometry>
        <box size="0 0 0"/>
      </geometry>
    </collision>
    <inertial>
      <mass value="1.0"/>
      <inertia ixx="0.015" iyy="0.0375" izz="0.0375" ixy="0" ixz="0" iyz="0"/>
    </inertial>
  </link>

  <joint name="sat_solar_left_joint" type="fixed">
    <parent link="sat_link"/>
    <child link="sat_solar_left_link"/>
    <axis xyz="1 0 0"/>
    <origin rpy="1.57 0 1.57" xyz="0 1.1 0"/>
  </joint>

  <link name="sat_solar_right_link">
    <visual>
      <geometry>
        <box size="0.7 0.3 0.1"/>
      </geometry>
      <material name="silver">
        <color rgba="0.75 0.75 0.75 1"/>
      </material>
    </visual>
    <collision>
      <geometry>
        <box size="0 0 0"/>
      </geometry>
    </collision>
    <inertial>
      <mass value="1.0"/>
      <inertia ixx="0.015" iyy="0.0375" izz="0.0375" ixy="0" ixz="0" iyz="0"/>
    </inertial>
  </link>

  <joint name="sat_solar_right_joint" type="fixed">
    <parent link="sat_link"/>
    <child link="sat_solar_right_link"/>
    <axis xyz="-1 0 0"/>
    <origin rpy="1.57 0 1.57" xyz="0 -1.1 0"/>
  </joint>


  <link name="arm_base_link">
  <visual>
    <geometry>
      <cylinder length="0.05" radius="0.1"/>
    </geometry>
    <material name="silver">
      <color rgba="0.75 0.75 0.75 1"/>
    </material>
    <origin rpy="0 0 0" xyz="0 0 0.025"/>
    </visual>
    <collision>
      <geometry>
        <cylinder length="0.05" radius="0.1"/>
      </geometry>
      <origin rpy="0 0 0" xyz="0 0 0.025"/>
    </collision>
    <inertial>
      <mass value="1.0"/>
      <origin rpy="0 0 0" xyz="0 0 0.025"/>
      <inertia ixx="0.0027" iyy="0.0027" izz="0.005" ixy="0" ixz="0" iyz="0"/>
    </inertial>
  </link>

  <joint name="fixed" type="fixed">
    <parent link="base_link"/>
    <child link="arm_base_link"/>
  </joint>

  <link name="leg">
    <visual>
      <geometry>
        <cylinder length="0.5" radius="0.05"/>
      </geometry>
      <material name="silver">
        <color rgba="0.75 0.75 0.75 1"/>
      </material>
      <origin rpy="0 0 0" xyz="0 0 0.25"/>
    </visual>
    <collision>
      <geometry>
        <cylinder length="0.5" radius="0.05"/>
      </geometry>
      <origin rpy="0 0 0" xyz="0 0 0.25"/>
    </collision>
    <inertial>
      <mass value="1.0"/>
      <origin rpy="0 0 0" xyz="0 0 0.25"/>
      <inertia ixx="0.02146" iyy="0.02146" izz="0.00125" ixy="0" ixz="0" iyz="0"/>
    </inertial>
  </link>

  <joint name="pelvis" type="continuous">
    <axis xyz="0 0 1"/>
    <parent link="arm_base_link"/>
    <child link="leg"/>
    <origin rpy="0 0 0" xyz="0.0 0.0 0.05"/>
  </joint>

  <link name="torso">
    <visual>
      <geometry>
        <cylinder length="0.4" radius="0.05"/>
      </geometry>
      <material name="silver">
        <color rgba="0.75 0.75 0.75 1"/>
      </material>
      <origin rpy="0 0 0" xyz="0 0 0.2"/>
    </visual>
    <collision>
      <geometry>
        <cylinder length="0.4" radius="0.05"/>
      </geometry>
      <origin rpy="0 0 0" xyz="0 0 0.2"/>
    </collision>
    <inertial>
      <mass value="1.0"/>
      <origin rpy="0 0 0" xyz="0 0 0.2"/>
      <inertia ixx="0.01396" iyy="0.01396" izz="0.00125" ixy="0" ixz="0" iyz="0"/>
    </inertial>
  </link>
  
  <joint name="hip" type="continuous">
    <axis xyz="0 1 0"/>
    <parent link="leg"/>
    <child link="torso"/>
    <origin rpy="0 1.5708 0" xyz="0.0 -0.1 0.45"/>
  </joint>

  <!-- <link name="upper_arm"> -->
    <!-- <visual> -->
      <!-- <geometry> -->
        <!-- <cylinder length="0.4" radius="0.05"/> -->
      <!-- </geometry> -->
      <!-- <material name="silver"/> -->
      <!-- <origin rpy="0 0 0" xyz="0 0 0.2"/> -->
    <!-- </visual> -->
    <!-- <collision> -->
      <!-- <geometry> -->
        <!-- <cylinder length="0.4" radius="0.05"/> -->
      <!-- </geometry> -->
      <!-- <origin rpy="0 0 0" xyz="0 0 0.2"/> -->
    <!-- </collision> -->
    <!-- <inertial> -->
      <!-- <mass value="1.0"/> -->
      <!-- <origin rpy="0 0 0" xyz="0 0 0.2"/> -->
      <!-- <inertia ixx="0.01396" iyy="0.0" izz="0.00" ixy="0" ixz="0" iyz="0"/> -->
    <!-- </inertial> -->
  <!-- </link> -->

  <!-- <joint name="shoulder" type="continuous"> -->
    <!-- <axis xyz="0 1 0"/> -->
    <!-- <parent link="torso"/> -->
    <!-- <child link="upper_arm"/> -->
    <!-- <origin rpy="0 0 0" xyz="0.0 0.1 0.35"/> -->
  <!-- </joint> -->

  <!-- <link name="lower_arm"> -->
  <!-- <gravity>0</gravity> -->
    <!-- <visual> -->
      <!-- <geometry> -->
        <!-- <cylinder length="0.4" radius="0.05"/> -->
      <!-- </geometry> -->
      <!-- <material name="silver"/> -->
      <!-- <origin rpy="0 0 0" xyz="0 0 0.2"/> -->
    <!-- </visual> -->
    <!-- <collision> -->
      <!-- <geometry> -->
        <!-- <cylinder length="0.4" radius="0.05"/> -->
      <!-- </geometry> -->
      <!-- <origin rpy="0 0 0" xyz="0 0 0.2"/> -->
    <!-- </collision> -->
    <!-- <inertial> -->
      <!-- <mass value="1.0"/> -->
      <!-- <origin rpy="0 0 0" xyz="0 0 0.2"/> -->
      <!-- <inertia ixx="0.01396" iyy="0.01396" izz="0.00" ixy="0" ixz="0" iyz="0"/> -->
    <!-- </inertial> -->
  <!-- </link> -->

  <!-- <joint name="elbow" type="continuous"> -->
    <!-- <axis xyz="0 1 0"/> -->
    <!-- <parent link="upper_arm"/> -->
    <!-- <child link="lower_arm"/> -->
    <!-- <origin rpy="0 0 0" xyz="0.0 -0.1 0.35"/> -->
  <!-- </joint> -->

  <link name="hand">
    <visual>
      <geometry>
        <box size="0.1 0.1 0.1"/>
      </geometry>
      <material name="silver"/>
    </visual>
    <collision>
      <geometry>
        <box size="0.0 0.0 0.0"/>
      </geometry>
    </collision>
    <inertial>
      <mass value="1.0"/>
      <inertia ixx="0.00042" iyy="0.00042" izz="0.00042" ixy="0" ixz="0" iyz="0"/>
    </inertial>
  </link>
  
  <joint name="wrist" type="continuous">
    <axis xyz="0 0 1"/>
    <parent link="torso"/>
    <child link="hand"/>
    <origin rpy="0 0 0" xyz="0.0 0.1 0.425"/>
  </joint>

  <link name="camera_link">
    <collision>
      <origin xyz="0 0 0" rpy="0 0 0"/>
      <geometry>
        <box size="0.05 0.05 0.05"/>
      </geometry>
    </collision>
    <visual>
      <origin xyz="0 0 0" rpy="0 0 0"/>
      <geometry>
        <box size="0.05 0.05 0.05"/>
      </geometry>
      <material name="red">
        <color rgba="0.75 0 0 1"/>
      </material>
    </visual>
    <inertial>
      <mass value="1e-5" />
      <origin xyz="0 0 0" rpy="0 0 0"/>
      <inertia ixx="1e-6" ixy="0" ixz="0" iyy="1e-6" iyz="0" izz="1e-6" />
    </inertial>
  </link>

  <joint name="elbow" type="continuous">
    <axis xyz="0 1 0" />
    <origin xyz="0.0 0.0 0.05" rpy="0 -1.5708 0"/>
    <parent link="hand"/>
    <child link="camera_link"/>
  </joint>

  <!-- This file is a placeholder which is included by default from
       husky.urdf.xacro. If a robot is being customized and requires
       additional URDF, set the HUSKY_URDF_EXTRAS environment variable
       to the full path of the file you would like included. -->
  <!-- Additional definitions for simulation -->
  <!-- <gazebo reference="base_link">
        <material>Gazebo/Grey</material>
    </gazebo> -->
  <transmission name="front_right_wheel_trans" type="SimpleTransmission">
    <type>transmission_interface/SimpleTransmission</type>
    <actuator name="front_right_wheel_motor">
      <mechanicalReduction>1</mechanicalReduction>
    </actuator>
    <joint name="front_right_wheel">
      <hardwareInterface>hardware_interface/VelocityJointInterface</hardwareInterface>
    </joint>
  </transmission>
  <transmission name="front_left_wheel_trans" type="SimpleTransmission">
    <type>transmission_interface/SimpleTransmission</type>
    <actuator name="front_left_wheel_motor">
      <mechanicalReduction>1</mechanicalReduction>
    </actuator>
    <joint name="front_left_wheel">
      <hardwareInterface>hardware_interface/VelocityJointInterface</hardwareInterface>
    </joint>
  </transmission>
  <transmission name="rear_left_wheel_trans" type="SimpleTransmission">
    <type>transmission_interface/SimpleTransmission</type>
    <actuator name="rear_left_wheel_motor">
      <mechanicalReduction>1</mechanicalReduction>
    </actuator>
    <joint name="rear_left_wheel">
      <hardwareInterface>hardware_interface/VelocityJointInterface</hardwareInterface>
    </joint>
  </transmission>
  <transmission name="rear_right_wheel_trans" type="SimpleTransmission">
    <type>transmission_interface/SimpleTransmission</type>
    <actuator name="rear_right_wheel_motor">
      <mechanicalReduction>1</mechanicalReduction>
    </actuator>
    <joint name="rear_right_wheel">
      <hardwareInterface>hardware_interface/VelocityJointInterface</hardwareInterface>
    </joint>
  </transmission>
  <transmission name="tran0" type="SimpleTransmission">
    <type>transmission_interface/SimpleTransmission</type>
    <joint name="pelvis">
      <hardwareInterface>hardware_interface/VelocityJointInterface</hardwareInterface>
    </joint>
    <actuator name="motor0">
      <mechanicalReduction>1</mechanicalReduction>
    </actuator>
  </transmission>
  <transmission name="tran1" type="SimpleTransmission">
    <type>transmission_interface/SimpleTransmission</type>
    <joint name="hip">
      <hardwareInterface>hardware_interface/VelocityJointInterface</hardwareInterface>
    </joint>
    <actuator name="motor1">
      <mechanicalReduction>1</mechanicalReduction>
    </actuator>
  </transmission>
  <!-- <transmission name="tran2" type="SimpleTransmission"> -->
    <!-- <type>transmission_interface/SimpleTransmission</type> -->
    <!-- <joint name="shoulder"> -->
      <!-- <hardwareInterface>hardware_interface/VelocityJointInterface</hardwareInterface> -->
    <!-- </joint> -->
    <!-- <actuator name="motor2"> -->
      <!-- <mechanicalReduction>1</mechanicalReduction> -->
    <!-- </actuator> -->
  <!-- </transmission> -->
  <transmission name="tran2" type="SimpleTransmission">
    <type>transmission_interface/SimpleTransmission</type>
    <joint name="elbow">
      <hardwareInterface>hardware_interface/VelocityJointInterface</hardwareInterface>
    </joint>
    <actuator name="motor2">
      <mechanicalReduction>1</mechanicalReduction>
    </actuator>
  </transmission>
  <transmission name="tran3" type="SimpleTransmission">
    <type>transmission_interface/SimpleTransmission</type>
    <joint name="wrist">
      <hardwareInterface>hardware_interface/VelocityJointInterface</hardwareInterface>
    </joint>
    <actuator name="motor3">
      <!-- <hardwareInterface>PositionJointInterface</hardwareInterface> -->
      <mechanicalReduction>1</mechanicalReduction>
    </actuator>
  </transmission>
  <!-- Controller configurations -->
  <gazebo>
    <plugin filename="libgazebo_ros_control.so" name="control">
      <robotNamespace>/</robotNamespace>
    </plugin>
  </gazebo>
  <!-- kp spring constant, kd damping constant -->
  <!-- <gazebo>
    <plugin name="joint_state_publisher" filename="libgazebo_ros_joint_state_publisher.so">
      <jointName>pelvis, hip, elbow, wrist</jointName>
    </plugin> -->
    <!-- <mu1 value="1.0"/> -->
    <!-- <mu2 value="0.9"/> -->
    <!-- <kp value="10000000.0"/> -->
    <!-- <kd value="1.0"/> -->
    <!-- <fdir1 value="1 0 0"/> -->
    <!-- <minDepth value="0.001"/> -->
    <!-- <maxContacts value="64"/> -->
  <!-- </gazebo> -->
  
  <gazebo reference="camera_link">
    <sensor type="camera" name="arm_camera">
      <update_rate>30.0</update_rate>
      <camera name="head">
        <horizontal_fov>1.3962634</horizontal_fov>
        <image>
          <width>600</width>
          <height>600</height>
          <!-- <format>R8G8B8</format> -->
        </image>
        <clip>
          <near>0.02</near>
          <far>300</far>
        </clip>
        <noise>
          <type>gaussian</type>
          <!-- Noise is sampled independently per pixel on each frame.
               That pixel's noise value is added to each of its color
               channels, which at that point lie in the range [0,1]. -->
          <mean>0.0</mean>
          <stddev>0.007</stddev>
        </noise>
      </camera>
      <plugin name="camera_controller" filename="libgazebo_ros_camera.so">
        <alwaysOn>true</alwaysOn>
        <updateRate>0.0</updateRate>
        <cameraName>arm_camera</cameraName>
        <imageTopicName>image_raw</imageTopicName>
        <cameraInfoTopicName>camera_info</cameraInfoTopicName>
        <frameName>camera_link</frameName>
        <hackBaseline>0.07</hackBaseline>
        <distortionK1>0.0</distortionK1>
        <distortionK2>0.0</distortionK2>
        <distortionK3>0.0</distortionK3>
        <distortionT1>0.0</distortionT1>
        <distortionT2>0.0</distortionT2>
      </plugin>
    </sensor>
  </gazebo>
  <!-- <gazebo>
        <plugin name="skid_steer_drive_controller" filename="libgazebo_ros_skid_steer_drive.so">
            <updateRate>100.0</updateRate>
            <robotNamespace></robotNamespace>
            <leftFrontJoint>front_left_wheel</leftFrontJoint>
            <rightFrontJoint>front_right_wheel</rightFrontJoint>
            <leftRearJoint>rear_left_wheel</leftRearJoint>
            <rightRearJoint>rear_right_wheel</rightRearJoint>
            <wheelSeparation>4</wheelSeparation>
            <wheelDiameter>0.32918</wheelDiameter>
            <robotBaseFrame>base_link</robotBaseFrame>
            <torque>1000</torque>
            <commandTopic>cmd_vel</commandTopic>
            <broadcastTF>true</broadcastTF>
            <odometryTopic>odom</odometryTopic>
            <odometryFrame>odom</odometryFrame>
            <covariance_x>0.000100</covariance_x>
            <covariance_y>0.000100</covariance_y>
            <covariance_yaw>0.010000</covariance_yaw>
        </plugin>
    </gazebo> -->
  <!-- <gazebo>
        <plugin name="object_controller" filename="libgazebo_ros_planar_move.so">
            <commandTopic>cmd_vel</commandTopic>
            <odometryTopic>odom</odometryTopic>
            <odometryFrame>odom</odometryFrame>
            <odometryRate>20.0</odometryRate>
            <robotBaseFrame>base_footprint</robotBaseFrame>
        </plugin>
    </gazebo> -->
</robot>
